Workbook

Sheet Read me
A1: SemaSmart course content template: Japanese, Unit 1 (draft)
A2: One row per answer option. An import script reads the content sheet and creates the course content. Same format as the German template.
A4: WHAT TO EDIT
A5: Edit the white cells in columns A to Q on the content sheet. Columns R to T (grey headers) are formulas: do not type there.
A6: To add a challenge: copy the option rows of an existing challenge (including columns R to T) to the bottom, give it a new unique key and challenge_order, then change the text.
A7: The first challenge on the content sheet (rows 2 to 4) is the worked example of the format.
A9: CHALLENGE TYPES
A10: SELECT: the student sees an English prompt and picks the matching Japanese card from a grid. Options are spoken when tapped.
A11: ASSIST: the student sees a Japanese word or phrase and picks its English meaning from a list.
A12: LISTEN: the student hears the audio of the correct option and picks the matching text from text-only cards. This type does not exist in the app yet: add it first (see the prompt in the chat) before importing these rows.
A14: RULES
A15: 1. Exactly one correct option per challenge and 2 to 4 options. The checks sheet and column T flag any breach.
... A31: COLUMN GUIDE (example values from the first challenge)
A32: column | B32: required | C32: what to enter | D32: example
A33: key | B33: yes | C33: Stable id of the challenge. Same on every option row of that challenge. Never change it once students use it. | D33: ja-u01-l01-c01
A34: course | B34: yes | C34: Course title exactly as in the app. Create the course in /admin first (title and flag image). | D34: Japanese
A35: unit_order / unit_title / unit_description | B35: yes | C35: Unit number, label and the one-line description shown on the unit banner. | D35: 1 / Unit 1 / Hiragana, greetings and numbers 1 to 5
A36: lesson_order / lesson_title | B36: yes | C36: Lesson number within the unit and its title. | D36: 1 / Vowels: あ い う え お
A37: challenge_order | B37: yes | C37: Position of the challenge within the lesson (1, 2, 3 ...). | D37: 1
A38: type | B38: yes | C38: SELECT, ASSIST or LISTEN (see below). | D38: SELECT
A39: question | B39: yes | C39: SELECT: the full English prompt. ASSIST: the Japanese word or phrase to translate. LISTEN: the instruction shown above the speaker button. | D39: Which one of these is "a"?
A40: option_text | B40: yes | C40: One answer option per row. 2 to 4 options per challenge. | D40: い
A41: correct | B41: yes | C41: TRUE for exactly one option per challenge, FALSE for the rest. | D41: =FALSE() -> FALSE
A42: image_file | B42: no | C42: Optional file name of an image in the app's public folder. Leave empty if there is none. | D42: (empty)
A43: audio_text | B43: no | C43: Text to turn into speech for this option. Required on the correct option of every LISTEN challenge. Empty for English options. | D43: kana, e.g. あ
A44: audio_file | B44: no | C44: Filled in by the audio pipeline later. Do not type here. | D44: (empty)
A45: status | B45: yes | C45: draft, reviewed or rejected (see workflow). | D45: draft
A46: notes | B46: no | C46: Free text for reviewers. Not imported. | D46: (empty)

Sheet content
A1: key | B1: course | C1: unit_order | D1: unit_title | E1: unit_description | F1: lesson_order | G1: lesson_title | H1: challenge_order | I1: type | J1: question | K1: option_text | L1: correct | M1: image_file | N1: audio_text | O1: audio_file | P1: status | Q1: notes | R1: options_in_challenge (calc) | S1: correct_in_challenge (calc) | T1: check (calc)
A2: ja-u01-l01-c01 | B2: Japanese | C2: 1 | D2: Unit 1 | E2: Hiragana, greetings and numbers 1 to 5 | F2: 1 | G2: Vowels: あ い う え お | H2: 1 | I2: SELECT | J2: Which one of these is "a"? | K2: い | L2: =FALSE() -> FALSE | N2: い | P2: draft | R2: =COUNTIF($A$2:$A$2000,A2) -> 3 | S2: =COUNTIFS($A$2:$A$2000,A2,$L$2:$L$2000,TRUE()) -> 1 | T2: =IF(AND(R2>=2,R2<=4,S2=1),"OK","CHECK") -> OK
A3: ja-u01-l01-c01 | B3: Japanese | C3: 1 | D3: Unit 1 | E3: Hiragana, greetings and numbers 1 to 5 | F3: 1 | G3: Vowels: あ い う え お | H3: 1 | I3: SELECT | J3: Which one of these is "a"? | K3: う | L3: =FALSE() -> FALSE | N3: う | P3: draft | R3: =COUNTIF($A$2:$A$2000,A3) -> 3 | S3: =COUNTIFS($A$2:$A$2000,A3,$L$2:$L$2000,TRUE()) -> 1 | T3: =IF(AND(R3>=2,R3<=4,S3=1),"OK","CHECK") -> OK
A4: ja-u01-l01-c01 | B4: Japanese | C4: 1 | D4: Unit 1 | E4: Hiragana, greetings and numbers 1 to 5 | F4: 1 | G4: Vowels: あ い う え お | H4: 1 | I4: SELECT | J4: Which one of these is "a"? | K4: あ | L4: =TRUE() -> TRUE | N4: あ | P4: draft | R4: =COUNTIF($A$2:$A$2000,A4) -> 3 | S4: =COUNTIFS($A$2:$A$2000,A4,$L$2:$L$2000,TRUE()) -> 1 | T4: =IF(AND(R4>=2,R4<=4,S4=1),"OK","CHECK") -> OK
A5: ja-u01-l01-c02 | B5: Japanese | C5: 1 | D5: Unit 1 | E5: Hiragana, greetings and numbers 1 to 5 | F5: 1 | G5: Vowels: あ い う え お | H5: 2 | I5: SELECT | J5: Which one of these is "i"? | K5: え | L5: =FALSE() -> FALSE | N5: え | P5: draft | R5: =COUNTIF($A$2:$A$2000,A5) -> 3 | S5: =COUNTIFS($A$2:$A$2000,A5,$L$2:$L$2000,TRUE()) -> 1 | T5: =IF(AND(R5>=2,R5<=4,S5=1),"OK","CHECK") -> OK
A6: ja-u01-l01-c02 | B6: Japanese | C6: 1 | D6: Unit 1 | E6: Hiragana, greetings and numbers 1 to 5 | F6: 1 | G6: Vowels: あ い う え お | H6: 2 | I6: SELECT | J6: Which one of these is "i"? | K6: い | L6: =TRUE() -> TRUE | N6: い | P6: draft | R6: =COUNTIF($A$2:$A$2000,A6) -> 3 | S6: =COUNTIFS($A$2:$A$2000,A6,$L$2:$L$2000,TRUE()) -> 1 | T6: =IF(AND(R6>=2,R6<=4,S6=1),"OK","CHECK") -> OK
A7: ja-u01-l01-c02 | B7: Japanese | C7: 1 | D7: Unit 1 | E7: Hiragana, greetings and numbers 1 to 5 | F7: 1 | G7: Vowels: あ い う え お | H7: 2 | I7: SELECT | J7: Which one of these is "i"? | K7: あ | L7: =FALSE() -> FALSE | N7: あ | P7: draft | R7: =COUNTIF($A$2:$A$2000,A7) -> 3 | S7: =COUNTIFS($A$2:$A$2000,A7,$L$2:$L$2000,TRUE()) -> 1 | T7: =IF(AND(R7>=2,R7<=4,S7=1),"OK","CHECK") -> OK
A8: ja-u01-l01-c03 | B8: Japanese | C8: 1 | D8: Unit 1 | E8: Hiragana, greetings and numbers 1 to 5 | F8: 1 | G8: Vowels: あ い う え お | H8: 3 | I8: SELECT | J8: Which one of these is "u"? | K8: う | L8: =TRUE() -> TRUE | N8: う | P8: draft | R8: =COUNTIF($A$2:$A$2000,A8) -> 3 | S8: =COUNTIFS($A$2:$A$2000,A8,$L$2:$L$2000,TRUE()) -> 1 | T8: =IF(AND(R8>=2,R8<=4,S8=1),"OK","CHECK") -> OK
A9: ja-u01-l01-c03 | B9: Japanese | C9: 1 | D9: Unit 1 | E9: Hiragana, greetings and numbers 1 to 5 | F9: 1 | G9: Vowels: あ い う え お | H9: 3 | I9: SELECT | J9: Which one of these is "u"? | K9: お | L9: =FALSE() -> FALSE | N9: お | P9: draft | R9: =COUNTIF($A$2:$A$2000,A9) -> 3 | S9: =COUNTIFS($A$2:$A$2000,A9,$L$2:$L$2000,TRUE()) -> 1 | T9: =IF(AND(R9>=2,R9<=4,S9=1),"OK","CHECK") -> OK
A10: ja-u01-l01-c03 | B10: Japanese | C10: 1 | D10: Unit 1 | E10: Hiragana, greetings and numbers 1 to 5 | F10: 1 | G10: Vowels: あ い う え お | H10: 3 | I10: SELECT | J10: Which one of these is "u"? | K10: い | L10: =FALSE() -> FALSE | N10: い | P10: draft | R10: =COUNTIF($A$2:$A$2000,A10) -> 3 | S10: =COUNTIFS($A$2:$A$2000,A10,$L$2:$L$2000,TRUE()) -> 1 | T10: =IF(AND(R10>=2,R10<=4,S10=1),"OK","CHECK") -> OK
A11: ja-u01-l01-c04 | B11: Japanese | C11: 1 | D11: Unit 1 | E11: Hiragana, greetings and numbers 1 to 5 | F11: 1 | G11: Vowels: あ い う え お | H11: 4 | I11: SELECT | J11: Which one of these is "e"? | K11: あ | L11: =FALSE() -> FALSE | N11: あ | P11: draft | R11: =COUNTIF($A$2:$A$2000,A11) -> 3 | S11: =COUNTIFS($A$2:$A$2000,A11,$L$2:$L$2000,TRUE()) -> 1 | T11: =IF(AND(R11>=2,R11<=4,S11=1),"OK","CHECK") -> OK
A12: ja-u01-l01-c04 | B12: Japanese | C12: 1 | D12: Unit 1 | E12: Hiragana, greetings and numbers 1 to 5 | F12: 1 | G12: Vowels: あ い う え お | H12: 4 | I12: SELECT | J12: Which one of these is "e"? | K12: お | L12: =FALSE() -> FALSE | N12: お | P12: draft | R12: =COUNTIF($A$2:$A$2000,A12) -> 3 | S12: =COUNTIFS($A$2:$A$2000,A12,$L$2:$L$2000,TRUE()) -> 1 | T12: =IF(AND(R12>=2,R12<=4,S12=1),"OK","CHECK") -> OK
A13: ja-u01-l01-c04 | B13: Japanese | C13: 1 | D13: Unit 1 | E13: Hiragana, greetings and numbers 1 to 5 | F13: 1 | G13: Vowels: あ い う え お | H13: 4 | I13: SELECT | J13: Which one of these is "e"? | K13: え | L13: =TRUE() -> TRUE | N13: え | P13: draft | R13: =COUNTIF($A$2:$A$2000,A13) -> 3 | S13: =COUNTIFS($A$2:$A$2000,A13,$L$2:$L$2000,TRUE()) -> 1 | T13: =IF(AND(R13>=2,R13<=4,S13=1),"OK","CHECK") -> OK
A14: ja-u01-l01-c05 | B14: Japanese | C14: 1 | D14: Unit 1 | E14: Hiragana, greetings and numbers 1 to 5 | F14: 1 | G14: Vowels: あ い う え お | H14: 5 | I14: SELECT | J14: Which one of these is "o"? | K14: お | L14: =TRUE() -> TRUE | N14: お | P14: draft | R14: =COUNTIF($A$2:$A$2000,A14) -> 3 | S14: =COUNTIFS($A$2:$A$2000,A14,$L$2:$L$2000,TRUE()) -> 1 | T14: =IF(AND(R14>=2,R14<=4,S14=1),"OK","CHECK") -> OK
A15: ja-u01-l01-c05 | B15: Japanese | C15: 1 | D15: Unit 1 | E15: Hiragana, greetings and numbers 1 to 5 | F15: 1 | G15: Vowels: あ い う え お | H15: 5 | I15: SELECT | J15: Which one of these is "o"? | K15: う | L15: =FALSE() -> FALSE | N15: う | P15: draft | R15: =COUNTIF($A$2:$A$2000,A15) -> 3 | S15: =COUNTIFS($A$2:$A$2000,A15,$L$2:$L$2000,TRUE()) -> 1 | T15: =IF(AND(R15>=2,R15<=4,S15=1),"OK","CHECK") -> OK
A16: ja-u01-l01-c05 | B16: Japanese | C16: 1 | D16: Unit 1 | E16: Hiragana, greetings and numbers 1 to 5 | F16: 1 | G16: Vowels: あ い う え お | H16: 5 | I16: SELECT | J16: Which one of these is "o"? | K16: え | L16: =FALSE() -> FALSE | N16: え | P16: draft | R16: =COUNTIF($A$2:$A$2000,A16) -> 3 | S16: =COUNTIFS($A$2:$A$2000,A16,$L$2:$L$2000,TRUE()) -> 1 | T16: =IF(AND(R16>=2,R16<=4,S16=1),"OK","CHECK") -> OK
A17: ja-u01-l01-c06 | B17: Japanese | C17: 1 | D17: Unit 1 | E17: Hiragana, greetings and numbers 1 to 5 | F17: 1 | G17: Vowels: あ い う え お | H17: 6 | I17: LISTEN | J17: Listen and choose what you hear | K17: お | L17: =FALSE() -> FALSE | N17: お | P17: draft | Q17: Single-kana audio: best recorded by a native speaker. | R17: =COUNTIF($A$2:$A$2000,A17) -> 3 | S17: =COUNTIFS($A$2:$A$2000,A17,$L$2:$L$2000,TRUE()) -> 1 | T17: =IF(AND(R17>=2,R17<=4,S17=1),"OK","CHECK") -> OK
A18: ja-u01-l01-c06 | B18: Japanese | C18: 1 | D18: Unit 1 | E18: Hiragana, greetings and numbers 1 to 5 | F18: 1 | G18: Vowels: あ い う え お | H18: 6 | I18: LISTEN | J18: Listen and choose what you hear | K18: あ | L18: =TRUE() -> TRUE | N18: あ | P18: draft | R18: =COUNTIF($A$2:$A$2000,A18) -> 3 | S18: =COUNTIFS($A$2:$A$2000,A18,$L$2:$L$2000,TRUE()) -> 1 | T18: =IF(AND(R18>=2,R18<=4,S18=1),"OK","CHECK") -> OK
A19: ja-u01-l01-c06 | B19: Japanese | C19: 1 | D19: Unit 1 | E19: Hiragana, greetings and numbers 1 to 5 | F19: 1 | G19: Vowels: あ い う え お | H19: 6 | I19: LISTEN | J19: Listen and choose what you hear | K19: い | L19: =FALSE() -> FALSE | N19: い | P19: draft | R19: =COUNTIF($A$2:$A$2000,A19) -> 3 | S19: =COUNTIFS($A$2:$A$2000,A19,$L$2:$L$2000,TRUE()) -> 1 | T19: =IF(AND(R19>=2,R19<=4,S19=1),"OK","CHECK") -> OK
A20: ja-u01-l01-c07 | B20: Japanese | C20: 1 | D20: Unit 1 | E20: Hiragana, greetings and numbers 1 to 5 | F20: 1 | G20: Vowels: あ い う え お | H20: 7 | I20: LISTEN | J20: Listen and choose what you hear | K20: い | L20: =FALSE() -> FALSE | N20: い | P20: draft | R20: =COUNTIF($A$2:$A$2000,A20) -> 3 | S20: =COUNTIFS($A$2:$A$2000,A20,$L$2:$L$2000,TRUE()) -> 1 | T20: =IF(AND(R20>=2,R20<=4,S20=1),"OK","CHECK") -> OK
A21: ja-u01-l01-c07 | B21: Japanese | C21: 1 | D21: Unit 1 | E21: Hiragana, greetings and numbers 1 to 5 | F21: 1 | G21: Vowels: あ い う え お | H21: 7 | I21: LISTEN | J21: Listen and choose what you hear | K21: え | L21: =TRUE() -> TRUE | N21: え | P21: draft | R21: =COUNTIF($A$2:$A$2000,A21) -> 3 | S21: =COUNTIFS($A$2:$A$2000,A21,$L$2:$L$2000,TRUE()) -> 1 | T21: =IF(AND(R21>=2,R21<=4,S21=1),"OK","CHECK") -> OK
A22: ja-u01-l01-c07 | B22: Japanese | C22: 1 | D22: Unit 1 | E22: Hiragana, greetings and numbers 1 to 5 | F22: 1 | G22: Vowels: あ い う え お | H22: 7 | I22: LISTEN | J22: Listen and choose what you hear | K22: お | L22: =FALSE() -> FALSE | N22: お | P22: draft | R22: =COUNTIF($A$2:$A$2000,A22) -> 3 | S22: =COUNTIFS($A$2:$A$2000,A22,$L$2:$L$2000,TRUE()) -> 1 | T22: =IF(AND(R22>=2,R22<=4,S22=1),"OK","CHECK") -> OK
A23: ja-u01-l01-c08 | B23: Japanese | C23: 1 | D23: Unit 1 | E23: Hiragana, greetings and numbers 1 to 5 | F23: 1 | G23: Vowels: あ い う え お | H23: 8 | I23: LISTEN | J23: Listen and choose what you hear | K23: う | L23: =TRUE() -> TRUE | N23: う | P23: draft | R23: =COUNTIF($A$2:$A$2000,A23) -> 3 | S23: =COUNTIFS($A$2:$A$2000,A23,$L$2:$L$2000,TRUE()) -> 1 | T23: =IF(AND(R23>=2,R23<=4,S23=1),"OK","CHECK") -> OK
A24: ja-u01-l01-c08 | B24: Japanese | C24: 1 | D24: Unit 1 | E24: Hiragana, greetings and numbers 1 to 5 | F24: 1 | G24: Vowels: あ い う え お | H24: 8 | I24: LISTEN | J24: Listen and choose what you hear | K24: あ | L24: =FALSE() -> FALSE | N24: あ | P24: draft | R24: =COUNTIF($A$2:$A$2000,A24) -> 3 | S24: =COUNTIFS($A$2:$A$2000,A24,$L$2:$L$2000,TRUE()) -> 1 | T24: =IF(AND(R24>=2,R24<=4,S24=1),"OK","CHECK") -> OK
A25: ja-u01-l01-c08 | B25: Japanese | C25: 1 | D25: Unit 1 | E25: Hiragana, greetings and numbers 1 to 5 | F25: 1 | G25: Vowels: あ い う え お | H25: 8 | I25: LISTEN | J25: Listen and choose what you hear | K25: え | L25: =FALSE() -> FALSE | N25: え | P25: draft | R25: =COUNTIF($A$2:$A$2000,A25) -> 3 | S25: =COUNTIFS($A$2:$A$2000,A25,$L$2:$L$2000,TRUE()) -> 1 | T25: =IF(AND(R25>=2,R25<=4,S25=1),"OK","CHECK") -> OK
A26: ja-u01-l02-c01 | B26: Japanese | C26: 1 | D26: Unit 1 | E26: Hiragana, greetings and numbers 1 to 5 | F26: 2 | G26: か行: か き く け こ | H26: 1 | I26: SELECT | J26: Which one of these is "ka"? | K26: か | L26: =TRUE() -> TRUE | N26: か | P26: draft | R26: =COUNTIF($A$2:$A$2000,A26) -> 3 | S26: =COUNTIFS($A$2:$A$2000,A26,$L$2:$L$2000,TRUE()) -> 1 | T26: =IF(AND(R26>=2,R26<=4,S26=1),"OK","CHECK") -> OK
A27: ja-u01-l02-c01 | B27: Japanese | C27: 1 | D27: Unit 1 | E27: Hiragana, greetings and numbers 1 to 5 | F27: 2 | G27: か行: か き く け こ | H27: 1 | I27: SELECT | J27: Which one of these is "ka"? | K27: き | L27: =FALSE() -> FALSE | N27: き | P27: draft | R27: =COUNTIF($A$2:$A$2000,A27) -> 3 | S27: =COUNTIFS($A$2:$A$2000,A27,$L$2:$L$2000,TRUE()) -> 1 | T27: =IF(AND(R27>=2,R27<=4,S27=1),"OK","CHECK") -> OK
A28: ja-u01-l02-c01 | B28: Japanese | C28: 1 | D28: Unit 1 | E28: Hiragana, greetings and numbers 1 to 5 | F28: 2 | G28: か行: か き く け こ | H28: 1 | I28: SELECT | J28: Which one of these is "ka"? | K28: く | L28: =FALSE() -> FALSE | N28: く | P28: draft | R28: =COUNTIF($A$2:$A$2000,A28) -> 3 | S28: =COUNTIFS($A$2:$A$2000,A28,$L$2:$L$2000,TRUE()) -> 1 | T28: =IF(AND(R28>=2,R28<=4,S28=1),"OK","CHECK") -> OK
A29: ja-u01-l02-c02 | B29: Japanese | C29: 1 | D29: Unit 1 | E29: Hiragana, greetings and numbers 1 to 5 | F29: 2 | G29: か行: か き く け こ | H29: 2 | I29: SELECT | J29: Which one of these is "ki"? | K29: か | L29: =FALSE() -> FALSE | N29: か | P29: draft | R29: =COUNTIF($A$2:$A$2000,A29) -> 3 | S29: =COUNTIFS($A$2:$A$2000,A29,$L$2:$L$2000,TRUE()) -> 1 | T29: =IF(AND(R29>=2,R29<=4,S29=1),"OK","CHECK") -> OK
A30: ja-u01-l02-c02 | B30: Japanese | C30: 1 | D30: Unit 1 | E30: Hiragana, greetings and numbers 1 to 5 | F30: 2 | G30: か行: か き く け こ | H30: 2 | I30: SELECT | J30: Which one of these is "ki"? | K30: き | L30: =TRUE() -> TRUE | N30: き | P30: draft | R30: =COUNTIF($A$2:$A$2000,A30) -> 3 | S30: =COUNTIFS($A$2:$A$2000,A30,$L$2:$L$2000,TRUE()) -> 1 | T30: =IF(AND(R30>=2,R30<=4,S30=1),"OK","CHECK") -> OK
A31: ja-u01-l02-c02 | B31: Japanese | C31: 1 | D31: Unit 1 | E31: Hiragana, greetings and numbers 1 to 5 | F31: 2 | G31: か行: か き く け こ | H31: 2 | I31: SELECT | J31: Which one of these is "ki"? | K31: け | L31: =FALSE() -> FALSE | N31: け | P31: draft | R31: =COUNTIF($A$2:$A$2000,A31) -> 3 | S31: =COUNTIFS($A$2:$A$2000,A31,$L$2:$L$2000,TRUE()) -> 1 | T31: =IF(AND(R31>=2,R31<=4,S31=1),"OK","CHECK") -> OK
A32: ja-u01-l02-c03 | B32: Japanese | C32: 1 | D32: Unit 1 | E32: Hiragana, greetings and numbers 1 to 5 | F32: 2 | G32: か行: か き く け こ | H32: 3 | I32: SELECT | J32: Which one of these is "ku"? | K32: こ | L32: =FALSE() -> FALSE | N32: こ | P32: draft | R32: =COUNTIF($A$2:$A$2000,A32) -> 3 | S32: =COUNTIFS($A$2:$A$2000,A32,$L$2:$L$2000,TRUE()) -> 1 | T32: =IF(AND(R32>=2,R32<=4,S32=1),"OK","CHECK") -> OK
A33: ja-u01-l02-c03 | B33: Japanese | C33: 1 | D33: Unit 1 | E33: Hiragana, greetings and numbers 1 to 5 | F33: 2 | G33: か行: か き く け こ | H33: 3 | I33: SELECT | J33: Which one of these is "ku"? | K33: く | L33: =TRUE() -> TRUE | N33: く | P33: draft | R33: =COUNTIF($A$2:$A$2000,A33) -> 3 | S33: =COUNTIFS($A$2:$A$2000,A33,$L$2:$L$2000,TRUE()) -> 1 | T33: =IF(AND(R33>=2,R33<=4,S33=1),"OK","CHECK") -> OK
A34: ja-u01-l02-c03 | B34: Japanese | C34: 1 | D34: Unit 1 | E34: Hiragana, greetings and numbers 1 to 5 | F34: 2 | G34: か行: か き く け こ | H34: 3 | I34: SELECT | J34: Which one of these is "ku"? | K34: き | L34: =FALSE() -> FALSE | N34: き | P34: draft | R34: =COUNTIF($A$2:$A$2000,A34) -> 3 | S34: =COUNTIFS($A$2:$A$2000,A34,$L$2:$L$2000,TRUE()) -> 1 | T34: =IF(AND(R34>=2,R34<=4,S34=1),"OK","CHECK") -> OK
A35: ja-u01-l02-c04 | B35: Japanese | C35: 1 | D35: Unit 1 | E35: Hiragana, greetings and numbers 1 to 5 | F35: 2 | G35: か行: か き く け こ | H35: 4 | I35: SELECT | J35: Which one of these is "ke"? | K35: く | L35: =FALSE() -> FALSE | N35: く | P35: draft | R35: =COUNTIF($A$2:$A$2000,A35) -> 3 | S35: =COUNTIFS($A$2:$A$2000,A35,$L$2:$L$2000,TRUE()) -> 1 | T35: =IF(AND(R35>=2,R35<=4,S35=1),"OK","CHECK") -> OK
A36: ja-u01-l02-c04 | B36: Japanese | C36: 1 | D36: Unit 1 | E36: Hiragana, greetings and numbers 1 to 5 | F36: 2 | G36: か行: か き く け こ | H36: 4 | I36: SELECT | J36: Which one of these is "ke"? | K36: か | L36: =FALSE() -> FALSE | N36: か | P36: draft | R36: =COUNTIF($A$2:$A$2000,A36) -> 3 | S36: =COUNTIFS($A$2:$A$2000,A36,$L$2:$L$2000,TRUE()) -> 1 | T36: =IF(AND(R36>=2,R36<=4,S36=1),"OK","CHECK") -> OK
A37: ja-u01-l02-c04 | B37: Japanese | C37: 1 | D37: Unit 1 | E37: Hiragana, greetings and numbers 1 to 5 | F37: 2 | G37: か行: か き く け こ | H37: 4 | I37: SELECT | J37: Which one of these is "ke"? | K37: け | L37: =TRUE() -> TRUE | N37: け | P37: draft | R37: =COUNTIF($A$2:$A$2000,A37) -> 3 | S37: =COUNTIFS($A$2:$A$2000,A37,$L$2:$L$2000,TRUE()) -> 1 | T37: =IF(AND(R37>=2,R37<=4,S37=1),"OK","CHECK") -> OK
A38: ja-u01-l02-c05 | B38: Japanese | C38: 1 | D38: Unit 1 | E38: Hiragana, greetings and numbers 1 to 5 | F38: 2 | G38: か行: か き く け こ | H38: 5 | I38: SELECT | J38: Which one of these is "ko"? | K38: け | L38: =FALSE() -> FALSE | N38: け | P38: draft | R38: =COUNTIF($A$2:$A$2000,A38) -> 3 | S38: =COUNTIFS($A$2:$A$2000,A38,$L$2:$L$2000,TRUE()) -> 1 | T38: =IF(AND(R38>=2,R38<=4,S38=1),"OK","CHECK") -> OK
A39: ja-u01-l02-c05 | B39: Japanese | C39: 1 | D39: Unit 1 | E39: Hiragana, greetings and numbers 1 to 5 | F39: 2 | G39: か行: か き く け こ | H39: 5 | I39: SELECT | J39: Which one of these is "ko"? | K39: こ | L39: =TRUE() -> TRUE | N39: こ | P39: draft | R39: =COUNTIF($A$2:$A$2000,A39) -> 3 | S39: =COUNTIFS($A$2:$A$2000,A39,$L$2:$L$2000,TRUE()) -> 1 | T39: =IF(AND(R39>=2,R39<=4,S39=1),"OK","CHECK") -> OK
A40: ja-u01-l02-c05 | B40: Japanese | C40: 1 | D40: Unit 1 | E40: Hiragana, greetings and numbers 1 to 5 | F40: 2 | G40: か行: か き く け こ | H40: 5 | I40: SELECT | J40: Which one of these is "ko"? | K40: く | L40: =FALSE() -> FALSE | N40: く | P40: draft | R40: =COUNTIF($A$2:$A$2000,A40) -> 3 | S40: =COUNTIFS($A$2:$A$2000,A40,$L$2:$L$2000,TRUE()) -> 1 | T40: =IF(AND(R40>=2,R40<=4,S40=1),"OK","CHECK") -> OK
...

Sheet checks
A1: Checks (all values are formulas over the content sheet)
A3: Option rows | B3: =COUNTA(content!A2:A2000) -> 120 | C3: Every row is one answer option.
A4: Challenges: SELECT | B4: =COUNTIFS(content!I2:I2000,"SELECT",content!L2:L2000,TRUE()) -> 13 | C4: Counts the correct option of each SELECT challenge.
A5: Challenges: ASSIST | B5: =COUNTIFS(content!I2:I2000,"ASSIST",content!L2:L2000,TRUE()) -> 16 | C5: Counts the correct option of each ASSIST challenge.
A6: Challenges: LISTEN | B6: =COUNTIFS(content!I2:I2000,"LISTEN",content!L2:L2000,TRUE()) -> 11 | C6: Counts the correct option of each LISTEN challenge.
A7: Challenges: total | B7: =B4+B5+B6 -> 40
A8: Rows flagged CHECK | B8: =COUNTIF(content!T2:T2000,"CHECK") -> 0 | C8: Must be 0: every challenge needs 2 to 4 options and exactly one correct.
A9: Rows with status draft | B9: =COUNTIF(content!P2:P2000,"draft") -> 120 | C9: Not imported to production.
A10: Rows with status reviewed | B10: =COUNTIF(content!P2:P2000,"reviewed") -> 0 | C10: Checked by a native speaker; eligible for production.
A11: Rows with status rejected | B11: =COUNTIF(content!P2:P2000,"rejected") -> 0 | C11: Ignored by the import.
